Workbook
Name _200: Startseite!#REF!
Name Abt.neu: Tabelle4!$N$3:$N$6
Name auswahl: Tabelle4!$R$1:$R$3
Name Beeinträchtigung: Tabelle4!$Q$1:$Q$4
Name Beeinträchtigungen: Tabelle4!$Q$2:$Q$9
Name bitte_auswählen_ja_nein: Tabelle4!$O$1:$O$5
Name df: Startseite!#REF!
Name Dienstalter: Tabelle4!$E$1:$E$3
Name Geburtsjahr: Tabelle4!$L$1:$L$7
Name Geburtsmonat: Tabelle4!$M$1:$M$12
Name Geburtstag: Tabelle4!$L$1:$L$30
Name Geschlecht: Tabelle4!$D$1:$D$2
Name Geschlecht1: Tabelle4!$D$1:$D$3
Name Lehrbefähigung: Tabelle4!$F$1:$F$2
Name Lehrbefähigung_neu: Tabelle4!$F$1:$F$3
Name Mitglied: Tabelle4!#REF!
Name Mitglied_neu: Tabelle4!$K$1:$K$2
Name Ort: Tabelle4!$N$1:$N$5
Name Schülerzahl: Tabelle4!$B$1:$B$3
Name Schulkonzept: Tabelle4!$A:$A
Name Schulkonzept_I: Startseite!#REF!
Name Schulprofil_neu: Tabelle4!$A$1:$A$4
Name sdf: Startseite!#REF!
Name Sport_AG: Tabelle4!$C$1:$C$4
Name Sportart_AG: Tabelle4!$H$1:$H$9
Name Sportart_Freizeit: Tabelle4!$I$1:$I$7
Name Sportart_Verein: Tabelle4!$G$1:$G$10
Name Stunden: Tabelle4!$J:$J
Name Stunden_neu: Tabelle4!$J$1:$J$3
Name Stunden_neuer: Tabelle4!$J$1:$J$4
Name Stunden..: Tabelle4!$J$1:$J$3
Name Testort: Tabelle4!$N$3:$N$4

Sheet Startseite
B1: Dateneingabemaske
B5: Name der Schule: | C5: Staatliche Grundschule Mustermann
B6: Ort: | C6: Musterhausen
B7: 6-stellige Schulnr.: | C7: 99999
B8: Klasse | C8: 3a
B9: Datum | C9: 30 | D9: 11 | E9: 2017
C18: > mit der Dateneingabe beginnen
C21: Hilfe zur Dateneingabe

Sheet Schülerprofil
C1: SCHÜLERPROFIL
N3: Hilfe zur Dateneingabe
N6: > weiter zur Eingabe der TEST-Daten
N10: < zurück zur Startseite
C12: Hinweis zu den Sportarten: *Große Sportspiele = Fuß-, Hand-, Volley- & Basketball
C13: Schüler/in | J13: Teilnahme an einer Sport-AG | N13: Mitglied im Sportverein
C14: Schülercode | D14: Geschlecht | E14: *Geburtsdatum gesamt | F14: Geburtsdatum | H14: Größe (cm) | I14: Gewicht (kg) | J14: Teilnahme | K14: Sport-AG 1 | L14: Sport-AG 2 | M14: Sport-AG 3 | N14: Mitglied | O14: Sportart 1 | P14: Sportart 2 | Q14: Sportart 3 | R14: Wie oft in der Woche wird die Sportart durchschnittlich betrieben (inkl. Wettkämpfe/Ligaspiele)?
C15: [max. 5 Zeichen] | D15: (m / w) | E15: (TT/MM/JJJJ) | F15: (M/JJJJ) | J15: (ja /nein) | N15: (ja / nein) | R15: Bei mehreren Sportarten bitte Anzahl addieren!
A16: Beispiel-Zeile | C16: a1 | D16: w | E16: 39695 | F16: 4 | G16: 2006 | H16: 140 | I16: 30 | J16: ja | K16: Kampfsport | L16: Große Sportspiele* | N16: ja | O16: Leichtathletik | R16: 2
B17: 1 | C17: B1 | D17: m | E17: 39766 | H17: 132 | I17: 33 | J17: nein | N17: nein
B18: 2 | C18: B2 | D18: m | E18: 39911 | H18: 140 | I18: 35 | J18: ja | K18: Große Sportspiele* | N18: ja | O18: Große Sportspiele* | R18: 3
B19: 3 | C19: B3 | D19: m | E19: 40003 | H19: 132 | I19: 26 | J19: ja | K19: Große Sportspiele* | L19: Große Sportspiele* | N19: ja | O19: Tanzen/Aerobic | R19: 1
B20: 4 | C20: B4 | D20: m | E20: 39744 | H20: 131 | I20: 24 | J20: ja | K20: Große Sportspiele* | L20: Große Sportspiele* | N20: nein
B21: 5 | C21: B5 | D21: m | E21: 39599 | H21: 142 | I21: 37 | J21: ja | K21: Große Sportspiele* | N21: nein
B22: 6 | C22: B6 | D22: m | E22: 39695 | H22: 140 | I22: 33 | J22: ja | K22: Große Sportspiele* | L22: Große Sportspiele* | N22: nein
B23: 7 | C23: B7 | D23: m | E23: 39260 | H23: 143 | I23: 30 | J23: ja | K23: Große Sportspiele* | N23: nein
B24: 8 | C24: B8 | D24: m | E24: 39709 | H24: 140 | I24: 30 | J24: nein | N24: nein
B25: 9 | C25: B9 | D25: m | E25: 39615 | H25: 147 | I25: 57 | J25: ja | K25: Große Sportspiele* | N25: nein
B26: 10 | C26: B10 | D26: m | E26: 39890 | H26: 145 | I26: 38 | J26: nein | N26: ja | O26: Große Sportspiele* | R26: 1
B27: 11 | C27: B11 | D27: w | E27: 39965 | H27: 127 | I27: 19 | J27: nein | N27: nein
B28: 12 | C28: B12 | D28: w | E28: 39754 | H28: 137 | I28: 34 | J28: ja | K28: Tanzen/Aerobic | N28: ja | O28: Schwimmen | R28: 2
B29: 13 | C29: B13 | D29: w | E29: 39956 | H29: 134 | I29: 27 | J29: nein | N29: ja | O29: Schwimmen | R29: 1
B30: 14 | C30: B14 | D30: w | E30: 40020 | H30: 132 | I30: 27 | J30: nein | N30: ja | O30: Tanzen/Aerobic | R30: 1
B31: 15 | C31: B15 | D31: w | E31: 39448 | H31: 145 | I31: 37 | J31: ja | K31: Tanzen/Aerobic | N31: nein
B32: 16 | C32: B16 | D32: w | E32: 39631 | H32: 140 | I32: 31 | J32: nein | N32: ja | O32: Schwimmen | R32: 1
B33: 17 | C33: B17 | D33: w | E33: 39714 | H33: 148 | I33: 42 | J33: ja | K33: Große Sportspiele* | L33: Tanzen/Aerobic | N33: nein
B34: 18 | C34: B18 | D34: w | E34: 39983 | H34: 142 | I34: 38 | J34: nein | N34: ja | O34: Schwimmen | P34: Tanzen/Aerobic | R34: 3
B35: 19 | C35: B19 | D35: w | E35: 39888 | H35: 136 | I35: 30 | J35: nein | N35: nein
B36: 20 | C36: B20 | D36: w | E36: 39920 | H36: 140 | I36: 35 | J36: nein | N36: ja | O36: Tanzen/Aerobic | R36: 1
B37: 21 | C37: B21 | D37: w | E37: 39957 | H37: 143 | I37: 31 | J37: nein | N37: ja | O37: Schwimmen | R37: 2
B38: 22 | C38: B22 | D38: w | E38: 40001 | H38: 134 | I38: 37 | J38: ja | K38: Tanzen/Aerobic | N38: nein
B39: 23 | J39: nein | N39: nein
B40: 24 | J40: nein | N40: nein
B41: 25 | J41: nein | N41: nein
B42: 26 | J42: nein | N42: nein
B43: 27 | J43: nein | N43: nein
B44: 28 | J44: nein | N44: nein
B45: 29 | J45: nein | N45: nein
B46: 30 | J46: nein | N46: nein
B47: 31 | J47: nein | N47: nein
...

Sheet TEST-Daten
I5: Hilfe zur Dateneingabe
I8: < zurück zum Schülerprofil
C14: Schülercode | D14: Inklusion | E14: 20-m-Sprint | F14: Medizinballstoßen | G14: Standweitsprung | H14: Einbeinstand | I14: Sternlauf | J14: 6-min-Lauf | K14: 6-min-Lauf [Runden] Eingabe absolvierte 54-m-Runden | L14: 6-min-Lauf [Pylonen] Eingabe erreichte Pylonen in letzter Runde | M14: 6-min-Lauf [m] automatische Meter-Berechnung | N14: Anmerkungen
D15: Förderschwerpunkt | E15: [sec] | F15: [m] | G15: [cm] | H15: [sec] | I15: [sec] | J15: [m] Selbsteingabe | N15: Hinweis zu Verletzungen, Unter-/Übergewicht, Ausführungsprobleme etc.
A16: Beispiel-Zeile | C16: g1 | D16: Sprache | E16: 4.4 | F16: 3.9 | G16: 129 | H16: 25 | I16: 28.5 | J16: 972 | K16: 17 | L16: 4 | M16: 954 | N16: Koordinationsprobleme beim Sternlauf
B17: 1 | C17: =Schülerprofil!C17 -> B1 | D17: / | E17: 4.2 | F17: 3.7 | G17: 140 | H17: 10 | I17: 31 | J17: 972
B18: 2 | C18: =Schülerprofil!C18 -> B2 | D18: / | E18: 4.4 | F18: 4.1 | G18: 124 | H18: 5 | I18: 23.7 | J18: 1071 | M18: =(K18*54)+(L18*9) -> 0
B19: 3 | C19: =Schülerprofil!C19 -> B3 | D19: / | E19: 3.9 | F19: 4 | G19: 138 | H19: 12 | I19: 25.2 | J19: 1116 | M19: =(K19*54)+(L19*9) -> 0
B20: 4 | C20: =Schülerprofil!C20 -> B4 | D20: / | E20: 4.3 | F20: 3.7 | G20: 159 | H20: 16 | J20: 1296 | M20: =(K20*54)+(L20*9) -> 0
B21: 5 | C21: =Schülerprofil!C21 -> B5 | D21: / | E21: 4.7 | F21: 3.9 | G21: 128 | H21: 14 | I21: 25 | J21: 918 | M21: =(K21*54)+(L21*9) -> 0
B22: 6 | C22: =Schülerprofil!C22 -> B6 | D22: / | E22: 4.3 | F22: 4.1 | G22: 135 | H22: 16 | J22: 963 | M22: =(K22*54)+(L22*9) -> 0
B23: 7 | C23: =Schülerprofil!C23 -> B7 | D23: Lernen | E23: 3.9 | F23: 3.1 | H23: 10 | J23: 1053 | M23: =(K23*54)+(L23*9) -> 0
B24: 8 | C24: =Schülerprofil!C24 -> B8 | D24: / | E24: 4.2 | F24: 3.6 | G24: 143 | H24: 8 | I24: 21.7 | J24: 1034 | M24: =(K24*54)+(L24*9) -> 0
B25: 9 | C25: =Schülerprofil!C25 -> B9 | D25: / | E25: 4.9 | F25: 4.7 | G25: 100 | H25: 7 | I25: 29.7 | J25: 756 | M25: =(K25*54)+(L25*9) -> 0
B26: 10 | C26: =Schülerprofil!C26 -> B10 | D26: / | E26: 4.3 | F26: 4.3 | G26: 112 | H26: 19 | J26: 1134
B27: 11 | C27: =Schülerprofil!C27 -> B11 | D27: / | E27: 4.3 | F27: 3.1 | H27: 43 | I27: 25 | J27: 1056
B28: 12 | C28: =Schülerprofil!C28 -> B12 | D28: / | E28: 4.7 | F28: 3.6 | G28: 110 | H28: 3 | I28: 29.7 | J28: 1026
B29: 13 | C29: =Schülerprofil!C29 -> B13 | D29: / | E29: 4.6 | F29: 2.9 | G29: 118 | H29: 6 | I29: 25 | J29: 1056
B30: 14 | C30: =Schülerprofil!C30 -> B14 | D30: / | E30: 4.3 | F30: 3.4 | H30: 11 | J30: 972
B31: 15 | C31: =Schülerprofil!C31 -> B15 | D31: / | E31: 4.1 | F31: 4.1 | H31: 13 | I31: 23 | J31: 1080
B32: 16 | C32: =Schülerprofil!C32 -> B16 | D32: / | E32: 4.3 | F32: 3.9 | G32: 140 | H32: 5 | I32: 25.4 | J32: 990
B33: 17 | C33: =Schülerprofil!C33 -> B17 | D33: / | E33: 4.3 | F33: 4.9 | G33: 130 | H33: 5 | I33: 25 | J33: 1017 | M33: =(K33*54)+(L33*9) -> 0
B34: 18 | C34: =Schülerprofil!C34 -> B18 | D34: / | E34: 4.4 | F34: 3.5 | G34: 128 | H34: 11 | J34: 1037 | M34: =(K34*54)+(L34*9) -> 0
B35: 19 | C35: =Schülerprofil!C35 -> B19 | D35: / | E35: 4.5 | F35: 2.7 | G35: 112 | H35: 8 | J35: 981 | M35: =(K35*54)+(L35*9) -> 0
B36: 20 | C36: =Schülerprofil!C36 -> B20 | D36: / | E36: 4.6 | F36: 3.4 | G36: 128 | H36: 3 | I36: 28 | J36: 1026 | M36: =(K36*54)+(L36*9) -> 0
B37: 21 | C37: =Schülerprofil!C37 -> B21 | D37: / | E37: 4.7 | F37: 3.4 | G37: 122 | H37: 3 | I37: 29 | J37: 1034 | M37: =(K37*54)+(L37*9) -> 0
B38: 22 | C38: =Schülerprofil!C38 -> B22 | D38: / | E38: 4.6 | F38: 3.1 | G38: 97 | H38: 4 | J38: 918 | M38: =(K38*54)+(L38*9) -> 0
B39: 23 | C39: =Schülerprofil!C39 -> 0 | D39: / | M39: =(K39*54)+(L39*9) -> 0
B40: 24 | C40: =Schülerprofil!C40 -> 0 | D40: / | M40: =(K40*54)+(L40*9) -> 0
B41: 25 | C41: =Schülerprofil!C41 -> 0 | D41: / | M41: =(K41*54)+(L41*9) -> 0
B42: 26 | C42: =Schülerprofil!C42 -> 0 | D42: / | M42: =(K42*54)+(L42*9) -> 0
B43: 27 | C43: =Schülerprofil!C43 -> 0 | D43: / | M43: =(K43*54)+(L43*9) -> 0
B44: 28 | C44: =Schülerprofil!C44 -> 0 | D44: / | M44: =(K44*54)+(L44*9) -> 0
B45: 29 | C45: =Schülerprofil!C45 -> 0 | D45: / | M45: =(K45*54)+(L45*9) -> 0
B46: 30 | C46: =Schülerprofil!C46 -> 0 | D46: / | M46: =(K46*54)+(L46*9) -> 0
B47: 31 | C47: =Schülerprofil!C47 -> 0 | D47: / | M47: =(K47*54)+(L47*9) -> 0
B48: 32 | C48: =Schülerprofil!C48 -> 0 | D48: / | M48: =(K48*54)+(L48*9) -> 0
B49: 33 | C49: =Schülerprofil!C49 -> 0 | D49: / | M49: =(K49*54)+(L49*9) -> 0
B50: 34 | C50: =Schülerprofil!C50 -> 0 | D50: / | M50: =(K50*54)+(L50*9) -> 0
... B164: 148 | C164: =Schülerprofil!C164 -> 0 | D164: / | M164: =(K164*54)+(L164*9) -> 0
...

Sheet Hilfe zur Dateneingabe
C2: Hilfe zur Dateneingabemaske
N9: < zurück zur Startseite
N12: < zurück zum Schülerprofil
N15: < zurück zu den TEST-Daten
N57: < zurück zur Startseite
N93: < zurück zum Schülerprofil
N132: < zurück zum Schülerprofil
N173: < zurück zu den TEST-Daten
N200: < zurück zu den TEST-Daten

Sheet Tabelle4
A1: FLEX | B1: < 200 | C1: 0 | D1: weiblich | E1: < 15 Jahre | F1: Studium | G1: Turnen/Gymnastik | H1: Turnen/Gymnastik | I1: Ballsport | J1: 1x | K1: ja | L1: 2001 | M1: 1 | R1: -bitte auswählen-
A2: Ganztag | B2: 200 - 300 | C2: 1 | D2: männlich | E2: 15 - 30 Jahre | F2: Weiterbildung | G2: Große Sportspiele* | H2: Große Sportspiele* | I2: Fahrrad fahren | J2: 2x | K2: nein | L2: 2002 | M2: 2 | Q2: / | R2: ja
A3: sportbetont | B3: > 300 | C3: 2 | D3: bitte wählen | E3: > 30 Jahre | F3: keine | G3: Kampfsport | H3: Kampfsport | I3: Inlineskate/Skateboarden | J3: 3x | L3: 2003 | M3: 3 | Q3: Lernen | R3: nein
A4: keines | C4: > 2 | G4: Leichtathletik | H4: Leichtathletik | I4: Laufen | J4: mehr als 3x | L4: 2004 | M4: 4 | Q4: Sprache
G5: Reiten/Voltigieren | H5: Reiten/Voltigieren | I5: Schwimmen | L5: 2005 | M5: 5 | Q5: emotionale & soziale Entw.
G6: Schwimmen | H6: Sonstige Spiele | I6: Tanzen/Aerobic | L6: 2006 | M6: 6 | Q6: geistige Entwicklung
G7: Sonstige Spiele | H7: Tanzen/Aerobic | I7: Andere | L7: 2007 | M7: 7 | Q7: Hören
G8: Tanzen/Aerobic | H8: Skisport | M8: 8 | Q8: körperl. & motor. Entw.
G9: Skisport | H9: Andere | M9: 9 | Q9: Sehen
G10: Andere | M10: 10
M11: 11
M12: 12
L14: nicht mehr voreingestellt

Sheet Tabelle1
